Workbook

Sheet Control Sheet
A1: Hakim Group | Payroll Reconciliation Tool
B4: Monthly Control Panel
B5: Tolerance - HG practices (%) | C5: 0.2
B6: Tolerance - HO2 practice (%) | C6: 0.05
B7: Minimum £ to flag | C7: 50
B8: Prior period label | C8: June 2026
B9: Current period label | C9: July 2026
B10: Rule: practices whose name contains 'Head Office' use the HO2 tolerance; all others use the HG tolerance. Edit only the gold cells above.
B12: Monthly steps
B13: 1. Export the six iTrent reports below for the current payroll run.
B14: 2. Check the prior-month Payment Breakdown export for an EXTRA leading 'Reference No' column (see warning below). Delete it if present so both months line up.
B15: 3. Clear old data from each paste tab (keep the header row) and paste the new export starting at the header row shown in 'Expected report layout' below.
B16: 4. Update the Prior/Current period labels above.
B17: 5. Open Summary, Exceptions, Zero Hours and Drilldown - they recalculate automatically.
B18: 6. Work through Exceptions top to bottom; use Drilldown to inspect any payroll number.
B19: 7. Agree totals on the Summary tab to BACS and to the payroll submissions.
B22: Expected report layout
B23: Report | C23: Paste tab | D23: Header row | E23: Data starts | F23: Key columns
B24: NPV Comparison (Net Pay) | C24: NPV Comparison | D24: 14 | E24: 15 | F24: D Payroll No, E Prior Net, F Current Net
B25: Payment Breakdown - current month | C25: Payment Breakdown Current | D25: 14 | E25: 15 | F25: D Practice, K.. Elements, last col Reference No
B26: Payment Breakdown - prior month | C26: Payment Breakdown Prior | D26: 14 | E26: 15 | F26: Same as above once the extra leading column is removed
B27: New Starters | C27: New Starters | D27: 13 | E27: 14 | F27: D Payroll No, K Personal Reference
B28: Leavers | C28: Leavers | D28: 11 | E28: 12 | F28: D Payroll No, K Personal Reference
B29: Structure report | C29: Structure | D29: 12 | E29: 13 | F29: L Position, N Basis, P Payroll Ref (MHR), AI Category
B32: ⚠ WARNING - PRIOR MONTH PAYMENT BREAKDOWN: some iTrent exports carry an extra leading 'Reference No' column that shifts Practice, elements and everything else one column to the right. If Practice does not land in column D and the first pay element does not land in column K on the 'Payment Breakdown Prior' tab, delete the extra leading column before pasting. Getting this wrong silently misaligns the whole comparison.

Sheet _Helpers
A1: PayrollNumber | B1: PriorNet | C1: CurrentNet | D1: Practice | E1: IsZeroHoursOnly | F1: IsMainList | G1: IsStarter | H1: IsLeaver | I1: PersonalRef | J1: IsPaired | K1: ToleranceGroupPct | L1: Diff | M1: DiffPct | N1: OverTolerance | O1: Flagged | P1: Status | Q1: NoPayNoLeaver | R1: IsReviewItem | S1: Priority | T1: BasicSalaryPrior | U1: BasicSalaryCurrent | V1: BasicSalaryPctChange | W1: Basic Salary | X1: Overtime | Y1: Bonus | Z1: Mileage Expenses | AA1: Other Expenses | AB1: SMP | AC1: SSP | AD1: Pension Deduction | AE1: Student Loan | AF1: Attachment of Earnings | AG1: On Call Allowance | AH1: Unsocial Hours Premium | AI1: MaxAbsDiff | AJ1: DriverElement | AK1: DriverDiffValue | AL1: RankKey
A2: =IF('NPV Comparison'!D15="","",'NPV Comparison'!D15) | B2: =IF('NPV Comparison'!E15="","",'NPV Comparison'!E15) | C2: =IF('NPV Comparison'!F15="","",'NPV Comparison'!F15) | D2: =IF($A2="","",IFERROR(INDEX(Structure!$E$13:$E$312,MATCH($A2,Structure!$P$13:$P$312,0)),"")) | E2: =IF($A2="",0,IF(COUNTIF(Structure!$P$13:$P$312,$A2)=0,0,IF(COUNTIFS(Structure!$P$13:$P$312,$A2,Structure!$N$13:$N$312,"<>Zero Hours")=0,1,0))) | F2: =IF($A2="",0,1-E2) | G2: =IF($A2="",0,IF(COUNTIF('New Starters'!$D$14:$D$73,$A2)>0,1,0)) | H2: =IF($A2="",0,IF(COUNTIF('Leavers'!$D$12:$D$71,$A2)>0,1,0)) | I2: =IF($A2="","",IFERROR(INDEX('New Starters'!$K$14:$K$73,MATCH($A2,'New Starters'!$D$14:$D$73,0)),IFERROR(INDEX('Leavers'!$K$12:$K$71,MATCH($A2,'Leavers'!$D$12:$D$71,0)),""))) | J2: =IF(AND(G2=1,I2<>"",COUNTIF('Leavers'!$K$12:$K$71,I2)>0),1,IF(AND(H2=1,I2<>"",COUNTIF('New Starters'!$K$14:$K$73,I2)>0),1,0)) | K2: =IF(ISNUMBER(SEARCH("Head Office",D2)),'Control Sheet'!$C$6,'Control Sheet'!$C$5) | L2: =IF(OR($A2="",AND(B2="",C2="")),"",IF(B2="",C2,IF(C2="",-B2,C2-B2))) | M2: =IFERROR(L2/B2,"") | N2: =IF($A2="",0,IF(OR(B2="",C2="",C2=0,AND(ISNUMBER(M2),ABS(M2)>K2)),1,0)) | O2: =IF(AND(N2=1,ABS(L2)>='Control Sheet'!$C$7,F2=1),1,0) | P2: =IF($A2="","",IF(F2=0,"Zero Hours",IF(J2=1,"Explained: Paired transfer",IF(AND(G2=1,H2=0,J2=0),"Explained: Starter",IF(AND(H2=1,G2=0,J2=0),"Explained: Leaver",IF(O2=1,"Review required","OK")))))) | Q2: =IF(AND(F2=1,OR(C2="",C2=0),H2=0,J2=0),1,0) | R2: =IF(F2=0,0,IF(P2="Review required",1,IF(AND(P2="Explained: Starter",ISNUMBER(C2),C2>=1500),1,0))) | S2: =IF(R2=0,"",IF(Q2=1,"High",IF(AND(P2="Explained: Starter",C2>=1500),"High",IF(ABS(L2)>=2000,"High",IF(ABS(L2)>=500,"Medium","Low"))))) | T2: =SUMIFS('Payment Breakdown Prior'!$S$15:$S$164,'Payment Breakdown Prior'!$AE$15:$AE$164,$A2) | U2: =SUMIFS('Payment Breakdown Current'!$S$15:$S$164,'Payment Breakdown Current'!$AE$15:$AE$164,$A2) | V2: =IFERROR((U2-T2)/T2,"") | W2: =(SUMIFS('Payment Breakdown Current'!$S$15:$S$164,'Payment Breakdown Current'!$AE$15:$AE$164,$A2))-(SUMIFS('Payment Breakdown Prior'!$S$15:$S$164,'Payment Breakdown Prior'!$AE$15:$AE$164,$A2)) | X2: =(SUMIFS('Payment Breakdown Current'!$T$15:$T$164,'Payment Breakdown Current'!$AE$15:$AE$164,$A2))-(SUMIFS('Payment Breakdown Prior'!$T$15:$T$164,'Payment Breakdown Prior'!$AE$15:$AE$164,$A2)) | Y2: =(SUMIFS('Payment Breakdown Current'!$U$15:$U$164,'Payment Breakdown Current'!$AE$15:$AE$164,$A2))-(SUMIFS('Payment Breakdown Prior'!$U$15:$U$164,'Payment Breakdown Prior'!$AE$15:$AE$164,$A2)) | Z2: =(SUMIFS('Payment Breakdown Current'!$V$15:$V$164,'Payment Breakdown Current'!$AE$15:$AE$164,$A2))-(SUMIFS('Payment Breakdown Prior'!$V$15:$V$164,'Payment Breakdown Prior'!$AE$15:$AE$164,$A2)) | AA2: =(SUMIFS('Payment Breakdown Current'!$W$15:$W$164,'Payment Breakdown Current'!$AE$15:$AE$164,$A2))-(SUMIFS('Payment Breakdown Prior'!$W$15:$W$164,'Payment Breakdown Prior'!$AE$15:$AE$164,$A2)) | AB2: =(SUMIFS('Payment Breakdown Current'!$X$15:$X$164,'Payment Breakdown Current'!$AE$15:$AE$164,$A2))-(SUMIFS('Payment Breakdown Prior'!$X$15:$X$164,'Payment Breakdown Prior'!$AE$15:$AE$164,$A2)) | AC2: =(SUMIFS('Payment Breakdown Current'!$Y$15:$Y$164,'Payment Breakdown Current'!$AE$15:$AE$164,$A2))-(SUMIFS('Payment Breakdown Prior'!$Y$15:$Y$164,'Payment Breakdown Prior'!$AE$15:$AE$164,$A2)) | AD2: =(SUMIFS('Payment Breakdown Current'!$Z$15:$Z$164,'Payment Breakdown Current'!$AE$15:$AE$164,$A2))-(SUMIFS('Payment Breakdown Prior'!$Z$15:$Z$164,'Payment Breakdown Prior'!$AE$15:$AE$164,$A2)) | AE2: =(SUMIFS('Payment Breakdown Current'!$AA$15:$AA$164,'Payment Breakdown Current'!$AE$15:$AE$164,$A2))-(SUMIFS('Payment Breakdown Prior'!$AA$15:$AA$164,'Payment Breakdown Prior'!$AE$15:$AE$164,$A2)) | AF2: =(SUMIFS('Payment Breakdown Current'!$AB$15:$AB$164,'Payment Breakdown Current'!$AE$15:$AE$164,$A2))-(SUMIFS('Payment Breakdown Prior'!$AB$15:$AB$164,'Payment Breakdown Prior'!$AE$15:$AE$164,$A2)) | AG2: =(SUMIFS('Payment Breakdown Current'!$AC$15:$AC$164,'Payment Breakdown Current'!$AE$15:$AE$164,$A2))-(SUMIFS('Payment Breakdown Prior'!$AC$15:$AC$164,'Payment Breakdown Prior'!$AE$15:$AE$164,$A2)) | AH2: =(SUMIFS('Payment Breakdown Current'!$AD$15:$AD$164,'Payment Breakdown Current'!$AE$15:$AE$164,$A2))-(SUMIFS('Payment Breakdown Prior'!$AD$15:$AD$164,'Payment Breakdown Prior'!$AE$15:$AE$164,$A2)) | AI2: {=MAX(ABS(W2:AH2))} | AJ2: {=IF(AI2<0.005,"",IFERROR(INDEX($W$1:$AH$1,MATCH(AI2,ABS(W2:AH2),0)),""))} | AK2: {=IF(AI2<0.005,"",IFERROR(INDEX(W2:AH2,MATCH(AI2,ABS(W2:AH2),0)),""))} | AL2: =IF(R2=1,ABS(L2)-ROW()/100000000,"")
A3: =IF('NPV Comparison'!D16="","",'NPV Comparison'!D16) | B3: =IF('NPV Comparison'!E16="","",'NPV Comparison'!E16) | C3: =IF('NPV Comparison'!F16="","",'NPV Comparison'!F16) | D3: =IF($A3="","",IFERROR(INDEX(Structure!$E$13:$E$312,MATCH($A3,Structure!$P$13:$P$312,0)),"")) | E3: =IF($A3="",0,IF(COUNTIF(Structure!$P$13:$P$312,$A3)=0,0,IF(COUNTIFS(Structure!$P$13:$P$312,$A3,Structure!$N$13:$N$312,"<>Zero Hours")=0,1,0))) | F3: =IF($A3="",0,1-E3) | G3: =IF($A3="",0,IF(COUNTIF('New Starters'!$D$14:$D$73,$A3)>0,1,0)) | H3: =IF($A3="",0,IF(COUNTIF('Leavers'!$D$12:$D$71,$A3)>0,1,0)) | I3: =IF($A3="","",IFERROR(INDEX('New Starters'!$K$14:$K$73,MATCH($A3,'New Starters'!$D$14:$D$73,0)),IFERROR(INDEX('Leavers'!$K$12:$K$71,MATCH($A3,'Leavers'!$D$12:$D$71,0)),""))) | J3: =IF(AND(G3=1,I3<>"",COUNTIF('Leavers'!$K$12:$K$71,I3)>0),1,IF(AND(H3=1,I3<>"",COUNTIF('New Starters'!$K$14:$K$73,I3)>0),1,0)) | K3: =IF(ISNUMBER(SEARCH("Head Office",D3)),'Control Sheet'!$C$6,'Control Sheet'!$C$5) | L3: =IF(OR($A3="",AND(B3="",C3="")),"",IF(B3="",C3,IF(C3="",-B3,C3-B3))) | M3: =IFERROR(L3/B3,"") | N3: =IF($A3="",0,IF(OR(B3="",C3="",C3=0,AND(ISNUMBER(M3),ABS(M3)>K3)),1,0)) | O3: =IF(AND(N3=1,ABS(L3)>='Control Sheet'!$C$7,F3=1),1,0) | P3: =IF($A3="","",IF(F3=0,"Zero Hours",IF(J3=1,"Explained: Paired transfer",IF(AND(G3=1,H3=0,J3=0),"Explained: Starter",IF(AND(H3=1,G3=0,J3=0),"Explained: Leaver",IF(O3=1,"Review required","OK")))))) | Q3: =IF(AND(F3=1,OR(C3="",C3=0),H3=0,J3=0),1,0) | R3: =IF(F3=0,0,IF(P3="Review required",1,IF(AND(P3="Explained: Starter",ISNUMBER(C3),C3>=1500),1,0))) | S3: =IF(R3=0,"",IF(Q3=1,"High",IF(AND(P3="Explained: Starter",C3>=1500),"High",IF(ABS(L3)>=2000,"High",IF(ABS(L3)>=500,"Medium","Low"))))) | T3: =SUMIFS('Payment Breakdown Prior'!$S$15:$S$164,'Payment Breakdown Prior'!$AE$15:$AE$164,$A3) | U3: =SUMIFS('Payment Breakdown Current'!$S$15:$S$164,'Payment Breakdown Current'!$AE$15:$AE$164,$A3) | V3: =IFERROR((U3-T3)/T3,"") | W3: =(SUMIFS('Payment Breakdown Current'!$S$15:$S$164,'Payment Breakdown Current'!$AE$15:$AE$164,$A3))-(SUMIFS('Payment Breakdown Prior'!$S$15:$S$164,'Payment Breakdown Prior'!$AE$15:$AE$164,$A3)) | X3: =(SUMIFS('Payment Breakdown Current'!$T$15:$T$164,'Payment Breakdown Current'!$AE$15:$AE$164,$A3))-(SUMIFS('Payment Breakdown Prior'!$T$15:$T$164,'Payment Breakdown Prior'!$AE$15:$AE$164,$A3)) | Y3: =(SUMIFS('Payment Breakdown Current'!$U$15:$U$164,'Payment Breakdown Current'!$AE$15:$AE$164,$A3))-(SUMIFS('Payment Breakdown Prior'!$U$15:$U$164,'Payment Breakdown Prior'!$AE$15:$AE$164,$A3)) | Z3: =(SUMIFS('Payment Breakdown Current'!$V$15:$V$164,'Payment Breakdown Current'!$AE$15:$AE$164,$A3))-(SUMIFS('Payment Breakdown Prior'!$V$15:$V$164,'Payment Breakdown Prior'!$AE$15:$AE$164,$A3)) | AA3: =(SUMIFS('Payment Breakdown Current'!$W$15:$W$164,'Payment Breakdown Current'!$AE$15:$AE$164,$A3))-(SUMIFS('Payment Breakdown Prior'!$W$15:$W$164,'Payment Breakdown Prior'!$AE$15:$AE$164,$A3)) | AB3: =(SUMIFS('Payment Breakdown Current'!$X$15:$X$164,'Payment Breakdown Current'!$AE$15:$AE$164,$A3))-(SUMIFS('Payment Breakdown Prior'!$X$15:$X$164,'Payment Breakdown Prior'!$AE$15:$AE$164,$A3)) | AC3: =(SUMIFS('Payment Breakdown Current'!$Y$15:$Y$164,'Payment Breakdown Current'!$AE$15:$AE$164,$A3))-(SUMIFS('Payment Breakdown Prior'!$Y$15:$Y$164,'Payment Breakdown Prior'!$AE$15:$AE$164,$A3)) | AD3: =(SUMIFS('Payment Breakdown Current'!$Z$15:$Z$164,'Payment Breakdown Current'!$AE$15:$AE$164,$A3))-(SUMIFS('Payment Breakdown Prior'!$Z$15:$Z$164,'Payment Breakdown Prior'!$AE$15:$AE$164,$A3)) | AE3: =(SUMIFS('Payment Breakdown Current'!$AA$15:$AA$164,'Payment Breakdown Current'!$AE$15:$AE$164,$A3))-(SUMIFS('Payment Breakdown Prior'!$AA$15:$AA$164,'Payment Breakdown Prior'!$AE$15:$AE$164,$A3)) | AF3: =(SUMIFS('Payment Breakdown Current'!$AB$15:$AB$164,'Payment Breakdown Current'!$AE$15:$AE$164,$A3))-(SUMIFS('Payment Breakdown Prior'!$AB$15:$AB$164,'Payment Breakdown Prior'!$AE$15:$AE$164,$A3)) | AG3: =(SUMIFS('Payment Breakdown Current'!$AC$15:$AC$164,'Payment Breakdown Current'!$AE$15:$AE$164,$A3))-(SUMIFS('Payment Breakdown Prior'!$AC$15:$AC$164,'Payment Breakdown Prior'!$AE$15:$AE$164,$A3)) | AH3: =(SUMIFS('Payment Breakdown Current'!$AD$15:$AD$164,'Payment Breakdown Current'!$AE$15:$AE$164,$A3))-(SUMIFS('Payment Breakdown Prior'!$AD$15:$AD$164,'Payment Breakdown Prior'!$AE$15:$AE$164,$A3)) | AI3: {=MAX(ABS(W3:AH3))} | AJ3: {=IF(AI3<0.005,"",IFERROR(INDEX($W$1:$AH$1,MATCH(AI3,ABS(W3:AH3),0)),""))} | AK3: {=IF(AI3<0.005,"",IFERROR(INDEX(W3:AH3,MATCH(AI3,ABS(W3:AH3),0)),""))} | AL3: =IF(R3=1,ABS(L3)-ROW()/100000000,"")
A4: =IF('NPV Comparison'!D17="","",'NPV Comparison'!D17) | B4: =IF('NPV Comparison'!E17="","",'NPV Comparison'!E17) | C4: =IF('NPV Comparison'!F17="","",'NPV Comparison'!F17) | D4: =IF($A4="","",IFERROR(INDEX(Structure!$E$13:$E$312,MATCH($A4,Structure!$P$13:$P$312,0)),"")) | E4: =IF($A4="",0,IF(COUNTIF(Structure!$P$13:$P$312,$A4)=0,0,IF(COUNTIFS(Structure!$P$13:$P$312,$A4,Structure!$N$13:$N$312,"<>Zero Hours")=0,1,0))) | F4: =IF($A4="",0,1-E4) | G4: =IF($A4="",0,IF(COUNTIF('New Starters'!$D$14:$D$73,$A4)>0,1,0)) | H4: =IF($A4="",0,IF(COUNTIF('Leavers'!$D$12:$D$71,$A4)>0,1,0)) | I4: =IF($A4="","",IFERROR(INDEX('New Starters'!$K$14:$K$73,MATCH($A4,'New Starters'!$D$14:$D$73,0)),IFERROR(INDEX('Leavers'!$K$12:$K$71,MATCH($A4,'Leavers'!$D$12:$D$71,0)),""))) | J4: =IF(AND(G4=1,I4<>"",COUNTIF('Leavers'!$K$12:$K$71,I4)>0),1,IF(AND(H4=1,I4<>"",COUNTIF('New Starters'!$K$14:$K$73,I4)>0),1,0)) | K4: =IF(ISNUMBER(SEARCH("Head Office",D4)),'Control Sheet'!$C$6,'Control Sheet'!$C$5) | L4: =IF(OR($A4="",AND(B4="",C4="")),"",IF(B4="",C4,IF(C4="",-B4,C4-B4))) | M4: =IFERROR(L4/B4,"") | N4: =IF($A4="",0,IF(OR(B4="",C4="",C4=0,AND(ISNUMBER(M4),ABS(M4)>K4)),1,0)) | O4: =IF(AND(N4=1,ABS(L4)>='Control Sheet'!$C$7,F4=1),1,0) | P4: =IF($A4="","",IF(F4=0,"Zero Hours",IF(J4=1,"Explained: Paired transfer",IF(AND(G4=1,H4=0,J4=0),"Explained: Starter",IF(AND(H4=1,G4=0,J4=0),"Explained: Leaver",IF(O4=1,"Review required","OK")))))) | Q4: =IF(AND(F4=1,OR(C4="",C4=0),H4=0,J4=0),1,0) | R4: =IF(F4=0,0,IF(P4="Review required",1,IF(AND(P4="Explained: Starter",ISNUMBER(C4),C4>=1500),1,0))) | S4: =IF(R4=0,"",IF(Q4=1,"High",IF(AND(P4="Explained: Starter",C4>=1500),"High",IF(ABS(L4)>=2000,"High",IF(ABS(L4)>=500,"Medium","Low"))))) | T4: =SUMIFS('Payment Breakdown Prior'!$S$15:$S$164,'Payment Breakdown Prior'!$AE$15:$AE$164,$A4) | U4: =SUMIFS('Payment Breakdown Current'!$S$15:$S$164,'Payment Breakdown Current'!$AE$15:$AE$164,$A4) | V4: =IFERROR((U4-T4)/T4,"") | W4: =(SUMIFS('Payment Breakdown Current'!$S$15:$S$164,'Payment Breakdown Current'!$AE$15:$AE$164,$A4))-(SUMIFS('Payment Breakdown Prior'!$S$15:$S$164,'Payment Breakdown Prior'!$AE$15:$AE$164,$A4)) | X4: =(SUMIFS('Payment Breakdown Current'!$T$15:$T$164,'Payment Breakdown Current'!$AE$15:$AE$164,$A4))-(SUMIFS('Payment Breakdown Prior'!$T$15:$T$164,'Payment Breakdown Prior'!$AE$15:$AE$164,$A4)) | Y4: =(SUMIFS('Payment Breakdown Current'!$U$15:$U$164,'Payment Breakdown Current'!$AE$15:$AE$164,$A4))-(SUMIFS('Payment Breakdown Prior'!$U$15:$U$164,'Payment Breakdown Prior'!$AE$15:$AE$164,$A4)) | Z4: =(SUMIFS('Payment Breakdown Current'!$V$15:$V$164,'Payment Breakdown Current'!$AE$15:$AE$164,$A4))-(SUMIFS('Payment Breakdown Prior'!$V$15:$V$164,'Payment Breakdown Prior'!$AE$15:$AE$164,$A4)) | AA4: =(SUMIFS('Payment Breakdown Current'!$W$15:$W$164,'Payment Breakdown Current'!$AE$15:$AE$164,$A4))-(SUMIFS('Payment Breakdown Prior'!$W$15:$W$164,'Payment Breakdown Prior'!$AE$15:$AE$164,$A4)) | AB4: =(SUMIFS('Payment Breakdown Current'!$X$15:$X$164,'Payment Breakdown Current'!$AE$15:$AE$164,$A4))-(SUMIFS('Payment Breakdown Prior'!$X$15:$X$164,'Payment Breakdown Prior'!$AE$15:$AE$164,$A4)) | AC4: =(SUMIFS('Payment Breakdown Current'!$Y$15:$Y$164,'Payment Breakdown Current'!$AE$15:$AE$164,$A4))-(SUMIFS('Payment Breakdown Prior'!$Y$15:$Y$164,'Payment Breakdown Prior'!$AE$15:$AE$164,$A4)) | AD4: =(SUMIFS('Payment Breakdown Current'!$Z$15:$Z$164,'Payment Breakdown Current'!$AE$15:$AE$164,$A4))-(SUMIFS('Payment Breakdown Prior'!$Z$15:$Z$164,'Payment Breakdown Prior'!$AE$15:$AE$164,$A4)) | AE4: =(SUMIFS('Payment Breakdown Current'!$AA$15:$AA$164,'Payment Breakdown Current'!$AE$15:$AE$164,$A4))-(SUMIFS('Payment Breakdown Prior'!$AA$15:$AA$164,'Payment Breakdown Prior'!$AE$15:$AE$164,$A4)) | AF4: =(SUMIFS('Payment Breakdown Current'!$AB$15:$AB$164,'Payment Breakdown Current'!$AE$15:$AE$164,$A4))-(SUMIFS('Payment Breakdown Prior'!$AB$15:$AB$164,'Payment Breakdown Prior'!$AE$15:$AE$164,$A4)) | AG4: =(SUMIFS('Payment Breakdown Current'!$AC$15:$AC$164,'Payment Breakdown Current'!$AE$15:$AE$164,$A4))-(SUMIFS('Payment Breakdown Prior'!$AC$15:$AC$164,'Payment Breakdown Prior'!$AE$15:$AE$164,$A4)) | AH4: =(SUMIFS('Payment Breakdown Current'!$AD$15:$AD$164,'Payment Breakdown Current'!$AE$15:$AE$164,$A4))-(SUMIFS('Payment Breakdown Prior'!$AD$15:$AD$164,'Payment Breakdown Prior'!$AE$15:$AE$164,$A4)) | AI4: {=MAX(ABS(W4:AH4))} | AJ4: {=IF(AI4<0.005,"",IFERROR(INDEX($W$1:$AH$1,MATCH(AI4,ABS(W4:AH4),0)),""))} | AK4: {=IF(AI4<0.005,"",IFERROR(INDEX(W4:AH4,MATCH(AI4,ABS(W4:AH4),0)),""))} | AL4: =IF(R4=1,ABS(L4)-ROW()/100000000,"")
A5: =IF('NPV Comparison'!D18="","",'NPV Comparison'!D18) | B5: =IF('NPV Comparison'!E18="","",'NPV Comparison'!E18) | C5: =IF('NPV Comparison'!F18="","",'NPV Comparison'!F18) | D5: =IF($A5="","",IFERROR(INDEX(Structure!$E$13:$E$312,MATCH($A5,Structure!$P$13:$P$312,0)),"")) | E5: =IF($A5="",0,IF(COUNTIF(Structure!$P$13:$P$312,$A5)=0,0,IF(COUNTIFS(Structure!$P$13:$P$312,$A5,Structure!$N$13:$N$312,"<>Zero Hours")=0,1,0))) | F5: =IF($A5="",0,1-E5) | G5: =IF($A5="",0,IF(COUNTIF('New Starters'!$D$14:$D$73,$A5)>0,1,0)) | H5: =IF($A5="",0,IF(COUNTIF('Leavers'!$D$12:$D$71,$A5)>0,1,0)) | I5: =IF($A5="","",IFERROR(INDEX('New Starters'!$K$14:$K$73,MATCH($A5,'New Starters'!$D$14:$D$73,0)),IFERROR(INDEX('Leavers'!$K$12:$K$71,MATCH($A5,'Leavers'!$D$12:$D$71,0)),""))) | J5: =IF(AND(G5=1,I5<>"",COUNTIF('Leavers'!$K$12:$K$71,I5)>0),1,IF(AND(H5=1,I5<>"",COUNTIF('New Starters'!$K$14:$K$73,I5)>0),1,0)) | K5: =IF(ISNUMBER(SEARCH("Head Office",D5)),'Control Sheet'!$C$6,'Control Sheet'!$C$5) | L5: =IF(OR($A5="",AND(B5="",C5="")),"",IF(B5="",C5,IF(C5="",-B5,C5-B5))) | M5: =IFERROR(L5/B5,"") | N5: =IF($A5="",0,IF(OR(B5="",C5="",C5=0,AND(ISNUMBER(M5),ABS(M5)>K5)),1,0)) | O5: =IF(AND(N5=1,ABS(L5)>='Control Sheet'!$C$7,F5=1),1,0) | P5: =IF($A5="","",IF(F5=0,"Zero Hours",IF(J5=1,"Explained: Paired transfer",IF(AND(G5=1,H5=0,J5=0),"Explained: Starter",IF(AND(H5=1,G5=0,J5=0),"Explained: Leaver",IF(O5=1,"Review required","OK")))))) | Q5: =IF(AND(F5=1,OR(C5="",C5=0),H5=0,J5=0),1,0) | R5: =IF(F5=0,0,IF(P5="Review required",1,IF(AND(P5="Explained: Starter",ISNUMBER(C5),C5>=1500),1,0))) | S5: =IF(R5=0,"",IF(Q5=1,"High",IF(AND(P5="Explained: Starter",C5>=1500),"High",IF(ABS(L5)>=2000,"High",IF(ABS(L5)>=500,"Medium","Low"))))) | T5: =SUMIFS('Payment Breakdown Prior'!$S$15:$S$164,'Payment Breakdown Prior'!$AE$15:$AE$164,$A5) | U5: =SUMIFS('Payment Breakdown Current'!$S$15:$S$164,'Payment Breakdown Current'!$AE$15:$AE$164,$A5) | V5: =IFERROR((U5-T5)/T5,"") | W5: =(SUMIFS('Payment Breakdown Current'!$S$15:$S$164,'Payment Breakdown Current'!$AE$15:$AE$164,$A5))-(SUMIFS('Payment Breakdown Prior'!$S$15:$S$164,'Payment Breakdown Prior'!$AE$15:$AE$164,$A5)) | X5: =(SUMIFS('Payment Breakdown Current'!$T$15:$T$164,'Payment Breakdown Current'!$AE$15:$AE$164,$A5))-(SUMIFS('Payment Breakdown Prior'!$T$15:$T$164,'Payment Breakdown Prior'!$AE$15:$AE$164,$A5)) | Y5: =(SUMIFS('Payment Breakdown Current'!$U$15:$U$164,'Payment Breakdown Current'!$AE$15:$AE$164,$A5))-(SUMIFS('Payment Breakdown Prior'!$U$15:$U$164,'Payment Breakdown Prior'!$AE$15:$AE$164,$A5)) | Z5: =(SUMIFS('Payment Breakdown Current'!$V$15:$V$164,'Payment Breakdown Current'!$AE$15:$AE$164,$A5))-(SUMIFS('Payment Breakdown Prior'!$V$15:$V$164,'Payment Breakdown Prior'!$AE$15:$AE$164,$A5)) | AA5: =(SUMIFS('Payment Breakdown Current'!$W$15:$W$164,'Payment Breakdown Current'!$AE$15:$AE$164,$A5))-(SUMIFS('Payment Breakdown Prior'!$W$15:$W$164,'Payment Breakdown Prior'!$AE$15:$AE$164,$A5)) | AB5: =(SUMIFS('Payment Breakdown Current'!$X$15:$X$164,'Payment Breakdown Current'!$AE$15:$AE$164,$A5))-(SUMIFS('Payment Breakdown Prior'!$X$15:$X$164,'Payment Breakdown Prior'!$AE$15:$AE$164,$A5)) | AC5: =(SUMIFS('Payment Breakdown Current'!$Y$15:$Y$164,'Payment Breakdown Current'!$AE$15:$AE$164,$A5))-(SUMIFS('Payment Breakdown Prior'!$Y$15:$Y$164,'Payment Breakdown Prior'!$AE$15:$AE$164,$A5)) | AD5: =(SUMIFS('Payment Breakdown Current'!$Z$15:$Z$164,'Payment Breakdown Current'!$AE$15:$AE$164,$A5))-(SUMIFS('Payment Breakdown Prior'!$Z$15:$Z$164,'Payment Breakdown Prior'!$AE$15:$AE$164,$A5)) | AE5: =(SUMIFS('Payment Breakdown Current'!$AA$15:$AA$164,'Payment Breakdown Current'!$AE$15:$AE$164,$A5))-(SUMIFS('Payment Breakdown Prior'!$AA$15:$AA$164,'Payment Breakdown Prior'!$AE$15:$AE$164,$A5)) | AF5: =(SUMIFS('Payment Breakdown Current'!$AB$15:$AB$164,'Payment Breakdown Current'!$AE$15:$AE$164,$A5))-(SUMIFS('Payment Breakdown Prior'!$AB$15:$AB$164,'Payment Breakdown Prior'!$AE$15:$AE$164,$A5)) | AG5: =(SUMIFS('Payment Breakdown Current'!$AC$15:$AC$164,'Payment Breakdown Current'!$AE$15:$AE$164,$A5))-(SUMIFS('Payment Breakdown Prior'!$AC$15:$AC$164,'Payment Breakdown Prior'!$AE$15:$AE$164,$A5)) | AH5: =(SUMIFS('Payment Breakdown Current'!$AD$15:$AD$164,'Payment Breakdown Current'!$AE$15:$AE$164,$A5))-(SUMIFS('Payment Breakdown Prior'!$AD$15:$AD$164,'Payment Breakdown Prior'!$AE$15:$AE$164,$A5)) | AI5: {=MAX(ABS(W5:AH5))} | AJ5: {=IF(AI5<0.005,"",IFERROR(INDEX($W$1:$AH$1,MATCH(AI5,ABS(W5:AH5),0)),""))} | AK5: {=IF(AI5<0.005,"",IFERROR(INDEX(W5:AH5,MATCH(AI5,ABS(W5:AH5),0)),""))} | AL5: =IF(R5=1,ABS(L5)-ROW()/100000000,"")
A6: =IF('NPV Comparison'!D19="","",'NPV Comparison'!D19) | B6: =IF('NPV Comparison'!E19="","",'NPV Comparison'!E19) | C6: =IF('NPV Comparison'!F19="","",'NPV Comparison'!F19) | D6: =IF($A6="","",IFERROR(INDEX(Structure!$E$13:$E$312,MATCH($A6,Structure!$P$13:$P$312,0)),"")) | E6: =IF($A6="",0,IF(COUNTIF(Structure!$P$13:$P$312,$A6)=0,0,IF(COUNTIFS(Structure!$P$13:$P$312,$A6,Structure!$N$13:$N$312,"<>Zero Hours")=0,1,0))) | F6: =IF($A6="",0,1-E6) | G6: =IF($A6="",0,IF(COUNTIF('New Starters'!$D$14:$D$73,$A6)>0,1,0)) | H6: =IF($A6="",0,IF(COUNTIF('Leavers'!$D$12:$D$71,$A6)>0,1,0)) | I6: =IF($A6="","",IFERROR(INDEX('New Starters'!$K$14:$K$73,MATCH($A6,'New Starters'!$D$14:$D$73,0)),IFERROR(INDEX('Leavers'!$K$12:$K$71,MATCH($A6,'Leavers'!$D$12:$D$71,0)),""))) | J6: =IF(AND(G6=1,I6<>"",COUNTIF('Leavers'!$K$12:$K$71,I6)>0),1,IF(AND(H6=1,I6<>"",COUNTIF('New Starters'!$K$14:$K$73,I6)>0),1,0)) | K6: =IF(ISNUMBER(SEARCH("Head Office",D6)),'Control Sheet'!$C$6,'Control Sheet'!$C$5) | L6: =IF(OR($A6="",AND(B6="",C6="")),"",IF(B6="",C6,IF(C6="",-B6,C6-B6))) | M6: =IFERROR(L6/B6,"") | N6: =IF($A6="",0,IF(OR(B6="",C6="",C6=0,AND(ISNUMBER(M6),ABS(M6)>K6)),1,0)) | O6: =IF(AND(N6=1,ABS(L6)>='Control Sheet'!$C$7,F6=1),1,0) | P6: =IF($A6="","",IF(F6=0,"Zero Hours",IF(J6=1,"Explained: Paired transfer",IF(AND(G6=1,H6=0,J6=0),"Explained: Starter",IF(AND(H6=1,G6=0,J6=0),"Explained: Leaver",IF(O6=1,"Review required","OK")))))) | Q6: =IF(AND(F6=1,OR(C6="",C6=0),H6=0,J6=0),1,0) | R6: =IF(F6=0,0,IF(P6="Review required",1,IF(AND(P6="Explained: Starter",ISNUMBER(C6),C6>=1500),1,0))) | S6: =IF(R6=0,"",IF(Q6=1,"High",IF(AND(P6="Explained: Starter",C6>=1500),"High",IF(ABS(L6)>=2000,"High",IF(ABS(L6)>=500,"Medium","Low"))))) | T6: =SUMIFS('Payment Breakdown Prior'!$S$15:$S$164,'Payment Breakdown Prior'!$AE$15:$AE$164,$A6) | U6: =SUMIFS('Payment Breakdown Current'!$S$15:$S$164,'Payment Breakdown Current'!$AE$15:$AE$164,$A6) | V6: =IFERROR((U6-T6)/T6,"") | W6: =(SUMIFS('Payment Breakdown Current'!$S$15:$S$164,'Payment Breakdown Current'!$AE$15:$AE$164,$A6))-(SUMIFS('Payment Breakdown Prior'!$S$15:$S$164,'Payment Breakdown Prior'!$AE$15:$AE$164,$A6)) | X6: =(SUMIFS('Payment Breakdown Current'!$T$15:$T$164,'Payment Breakdown Current'!$AE$15:$AE$164,$A6))-(SUMIFS('Payment Breakdown Prior'!$T$15:$T$164,'Payment Breakdown Prior'!$AE$15:$AE$164,$A6)) | Y6: =(SUMIFS('Payment Breakdown Current'!$U$15:$U$164,'Payment Breakdown Current'!$AE$15:$AE$164,$A6))-(SUMIFS('Payment Breakdown Prior'!$U$15:$U$164,'Payment Breakdown Prior'!$AE$15:$AE$164,$A6)) | Z6: =(SUMIFS('Payment Breakdown Current'!$V$15:$V$164,'Payment Breakdown Current'!$AE$15:$AE$164,$A6))-(SUMIFS('Payment Breakdown Prior'!$V$15:$V$164,'Payment Breakdown Prior'!$AE$15:$AE$164,$A6)) | AA6: =(SUMIFS('Payment Breakdown Current'!$W$15:$W$164,'Payment Breakdown Current'!$AE$15:$AE$164,$A6))-(SUMIFS('Payment Breakdown Prior'!$W$15:$W$164,'Payment Breakdown Prior'!$AE$15:$AE$164,$A6)) | AB6: =(SUMIFS('Payment Breakdown Current'!$X$15:$X$164,'Payment Breakdown Current'!$AE$15:$AE$164,$A6))-(SUMIFS('Payment Breakdown Prior'!$X$15:$X$164,'Payment Breakdown Prior'!$AE$15:$AE$164,$A6)) | AC6: =(SUMIFS('Payment Breakdown Current'!$Y$15:$Y$164,'Payment Breakdown Current'!$AE$15:$AE$164,$A6))-(SUMIFS('Payment Breakdown Prior'!$Y$15:$Y$164,'Payment Breakdown Prior'!$AE$15:$AE$164,$A6)) | AD6: =(SUMIFS('Payment Breakdown Current'!$Z$15:$Z$164,'Payment Breakdown Current'!$AE$15:$AE$164,$A6))-(SUMIFS('Payment Breakdown Prior'!$Z$15:$Z$164,'Payment Breakdown Prior'!$AE$15:$AE$164,$A6)) | AE6: =(SUMIFS('Payment Breakdown Current'!$AA$15:$AA$164,'Payment Breakdown Current'!$AE$15:$AE$164,$A6))-(SUMIFS('Payment Breakdown Prior'!$AA$15:$AA$164,'Payment Breakdown Prior'!$AE$15:$AE$164,$A6)) | AF6: =(SUMIFS('Payment Breakdown Current'!$AB$15:$AB$164,'Payment Breakdown Current'!$AE$15:$AE$164,$A6))-(SUMIFS('Payment Breakdown Prior'!$AB$15:$AB$164,'Payment Breakdown Prior'!$AE$15:$AE$164,$A6)) | AG6: =(SUMIFS('Payment Breakdown Current'!$AC$15:$AC$164,'Payment Breakdown Current'!$AE$15:$AE$164,$A6))-(SUMIFS('Payment Breakdown Prior'!$AC$15:$AC$164,'Payment Breakdown Prior'!$AE$15:$AE$164,$A6)) | AH6: =(SUMIFS('Payment Breakdown Current'!$AD$15:$AD$164,'Payment Breakdown Current'!$AE$15:$AE$164,$A6))-(SUMIFS('Payment Breakdown Prior'!$AD$15:$AD$164,'Payment Breakdown Prior'!$AE$15:$AE$164,$A6)) | AI6: {=MAX(ABS(W6:AH6))} | AJ6: {=IF(AI6<0.005,"",IFERROR(INDEX($W$1:$AH$1,MATCH(AI6,ABS(W6:AH6),0)),""))} | AK6: {=IF(AI6<0.005,"",IFERROR(INDEX(W6:AH6,MATCH(AI6,ABS(W6:AH6),0)),""))} | AL6: =IF(R6=1,ABS(L6)-ROW()/100000000,"")
A7: =IF('NPV Comparison'!D20="","",'NPV Comparison'!D20) | B7: =IF('NPV Comparison'!E20="","",'NPV Comparison'!E20) | C7: =IF('NPV Comparison'!F20="","",'NPV Comparison'!F20) | D7: =IF($A7="","",IFERROR(INDEX(Structure!$E$13:$E$312,MATCH($A7,Structure!$P$13:$P$312,0)),"")) | E7: =IF($A7="",0,IF(COUNTIF(Structure!$P$13:$P$312,$A7)=0,0,IF(COUNTIFS(Structure!$P$13:$P$312,$A7,Structure!$N$13:$N$312,"<>Zero Hours")=0,1,0))) | F7: =IF($A7="",0,1-E7) | G7: =IF($A7="",0,IF(COUNTIF('New Starters'!$D$14:$D$73,$A7)>0,1,0)) | H7: =IF($A7="",0,IF(COUNTIF('Leavers'!$D$12:$D$71,$A7)>0,1,0)) | I7: =IF($A7="","",IFERROR(INDEX('New Starters'!$K$14:$K$73,MATCH($A7,'New Starters'!$D$14:$D$73,0)),IFERROR(INDEX('Leavers'!$K$12:$K$71,MATCH($A7,'Leavers'!$D$12:$D$71,0)),""))) | J7: =IF(AND(G7=1,I7<>"",COUNTIF('Leavers'!$K$12:$K$71,I7)>0),1,IF(AND(H7=1,I7<>"",COUNTIF('New Starters'!$K$14:$K$73,I7)>0),1,0)) | K7: =IF(ISNUMBER(SEARCH("Head Office",D7)),'Control Sheet'!$C$6,'Control Sheet'!$C$5) | L7: =IF(OR($A7="",AND(B7="",C7="")),"",IF(B7="",C7,IF(C7="",-B7,C7-B7))) | M7: =IFERROR(L7/B7,"") | N7: =IF($A7="",0,IF(OR(B7="",C7="",C7=0,AND(ISNUMBER(M7),ABS(M7)>K7)),1,0)) | O7: =IF(AND(N7=1,ABS(L7)>='Control Sheet'!$C$7,F7=1),1,0) | P7: =IF($A7="","",IF(F7=0,"Zero Hours",IF(J7=1,"Explained: Paired transfer",IF(AND(G7=1,H7=0,J7=0),"Explained: Starter",IF(AND(H7=1,G7=0,J7=0),"Explained: Leaver",IF(O7=1,"Review required","OK")))))) | Q7: =IF(AND(F7=1,OR(C7="",C7=0),H7=0,J7=0),1,0) | R7: =IF(F7=0,0,IF(P7="Review required",1,IF(AND(P7="Explained: Starter",ISNUMBER(C7),C7>=1500),1,0))) | S7: =IF(R7=0,"",IF(Q7=1,"High",IF(AND(P7="Explained: Starter",C7>=1500),"High",IF(ABS(L7)>=2000,"High",IF(ABS(L7)>=500,"Medium","Low"))))) | T7: =SUMIFS('Payment Breakdown Prior'!$S$15:$S$164,'Payment Breakdown Prior'!$AE$15:$AE$164,$A7) | U7: =SUMIFS('Payment Breakdown Current'!$S$15:$S$164,'Payment Breakdown Current'!$AE$15:$AE$164,$A7) | V7: =IFERROR((U7-T7)/T7,"") | W7: =(SUMIFS('Payment Breakdown Current'!$S$15:$S$164,'Payment Breakdown Current'!$AE$15:$AE$164,$A7))-(SUMIFS('Payment Breakdown Prior'!$S$15:$S$164,'Payment Breakdown Prior'!$AE$15:$AE$164,$A7)) | X7: =(SUMIFS('Payment Breakdown Current'!$T$15:$T$164,'Payment Breakdown Current'!$AE$15:$AE$164,$A7))-(SUMIFS('Payment Breakdown Prior'!$T$15:$T$164,'Payment Breakdown Prior'!$AE$15:$AE$164,$A7)) | Y7: =(SUMIFS('Payment Breakdown Current'!$U$15:$U$164,'Payment Breakdown Current'!$AE$15:$AE$164,$A7))-(SUMIFS('Payment Breakdown Prior'!$U$15:$U$164,'Payment Breakdown Prior'!$AE$15:$AE$164,$A7)) | Z7: =(SUMIFS('Payment Breakdown Current'!$V$15:$V$164,'Payment Breakdown Current'!$AE$15:$AE$164,$A7))-(SUMIFS('Payment Breakdown Prior'!$V$15:$V$164,'Payment Breakdown Prior'!$AE$15:$AE$164,$A7)) | AA7: =(SUMIFS('Payment Breakdown Current'!$W$15:$W$164,'Payment Breakdown Current'!$AE$15:$AE$164,$A7))-(SUMIFS('Payment Breakdown Prior'!$W$15:$W$164,'Payment Breakdown Prior'!$AE$15:$AE$164,$A7)) | AB7: =(SUMIFS('Payment Breakdown Current'!$X$15:$X$164,'Payment Breakdown Current'!$AE$15:$AE$164,$A7))-(SUMIFS('Payment Breakdown Prior'!$X$15:$X$164,'Payment Breakdown Prior'!$AE$15:$AE$164,$A7)) | AC7: =(SUMIFS('Payment Breakdown Current'!$Y$15:$Y$164,'Payment Breakdown Current'!$AE$15:$AE$164,$A7))-(SUMIFS('Payment Breakdown Prior'!$Y$15:$Y$164,'Payment Breakdown Prior'!$AE$15:$AE$164,$A7)) | AD7: =(SUMIFS('Payment Breakdown Current'!$Z$15:$Z$164,'Payment Breakdown Current'!$AE$15:$AE$164,$A7))-(SUMIFS('Payment Breakdown Prior'!$Z$15:$Z$164,'Payment Breakdown Prior'!$AE$15:$AE$164,$A7)) | AE7: =(SUMIFS('Payment Breakdown Current'!$AA$15:$AA$164,'Payment Breakdown Current'!$AE$15:$AE$164,$A7))-(SUMIFS('Payment Breakdown Prior'!$AA$15:$AA$164,'Payment Breakdown Prior'!$AE$15:$AE$164,$A7)) | AF7: =(SUMIFS('Payment Breakdown Current'!$AB$15:$AB$164,'Payment Breakdown Current'!$AE$15:$AE$164,$A7))-(SUMIFS('Payment Breakdown Prior'!$AB$15:$AB$164,'Payment Breakdown Prior'!$AE$15:$AE$164,$A7)) | AG7: =(SUMIFS('Payment Breakdown Current'!$AC$15:$AC$164,'Payment Breakdown Current'!$AE$15:$AE$164,$A7))-(SUMIFS('Payment Breakdown Prior'!$AC$15:$AC$164,'Payment Breakdown Prior'!$AE$15:$AE$164,$A7)) | AH7: =(SUMIFS('Payment Breakdown Current'!$AD$15:$AD$164,'Payment Breakdown Current'!$AE$15:$AE$164,$A7))-(SUMIFS('Payment Breakdown Prior'!$AD$15:$AD$164,'Payment Breakdown Prior'!$AE$15:$AE$164,$A7)) | AI7: {=MAX(ABS(W7:AH7))} | AJ7: {=IF(AI7<0.005,"",IFERROR(INDEX($W$1:$AH$1,MATCH(AI7,ABS(W7:AH7),0)),""))} | AK7: {=IF(AI7<0.005,"",IFERROR(INDEX(W7:AH7,MATCH(AI7,ABS(W7:AH7),0)),""))} | AL7: =IF(R7=1,ABS(L7)-ROW()/100000000,"")
A8: =IF('NPV Comparison'!D21="","",'NPV Comparison'!D21) | B8: =IF('NPV Comparison'!E21="","",'NPV Comparison'!E21) | C8: =IF('NPV Comparison'!F21="","",'NPV Comparison'!F21) | D8: =IF($A8="","",IFERROR(INDEX(Structure!$E$13:$E$312,MATCH($A8,Structure!$P$13:$P$312,0)),"")) | E8: =IF($A8="",0,IF(COUNTIF(Structure!$P$13:$P$312,$A8)=0,0,IF(COUNTIFS(Structure!$P$13:$P$312,$A8,Structure!$N$13:$N$312,"<>Zero Hours")=0,1,0))) | F8: =IF($A8="",0,1-E8) | G8: =IF($A8="",0,IF(COUNTIF('New Starters'!$D$14:$D$73,$A8)>0,1,0)) | H8: =IF($A8="",0,IF(COUNTIF('Leavers'!$D$12:$D$71,$A8)>0,1,0)) | I8: =IF($A8="","",IFERROR(INDEX('New Starters'!$K$14:$K$73,MATCH($A8,'New Starters'!$D$14:$D$73,0)),IFERROR(INDEX('Leavers'!$K$12:$K$71,MATCH($A8,'Leavers'!$D$12:$D$71,0)),""))) | J8: =IF(AND(G8=1,I8<>"",COUNTIF('Leavers'!$K$12:$K$71,I8)>0),1,IF(AND(H8=1,I8<>"",COUNTIF('New Starters'!$K$14:$K$73,I8)>0),1,0)) | K8: =IF(ISNUMBER(SEARCH("Head Office",D8)),'Control Sheet'!$C$6,'Control Sheet'!$C$5) | L8: =IF(OR($A8="",AND(B8="",C8="")),"",IF(B8="",C8,IF(C8="",-B8,C8-B8))) | M8: =IFERROR(L8/B8,"") | N8: =IF($A8="",0,IF(OR(B8="",C8="",C8=0,AND(ISNUMBER(M8),ABS(M8)>K8)),1,0)) | O8: =IF(AND(N8=1,ABS(L8)>='Control Sheet'!$C$7,F8=1),1,0) | P8: =IF($A8="","",IF(F8=0,"Zero Hours",IF(J8=1,"Explained: Paired transfer",IF(AND(G8=1,H8=0,J8=0),"Explained: Starter",IF(AND(H8=1,G8=0,J8=0),"Explained: Leaver",IF(O8=1,"Review required","OK")))))) | Q8: =IF(AND(F8=1,OR(C8="",C8=0),H8=0,J8=0),1,0) | R8: =IF(F8=0,0,IF(P8="Review required",1,IF(AND(P8="Explained: Starter",ISNUMBER(C8),C8>=1500),1,0))) | S8: =IF(R8=0,"",IF(Q8=1,"High",IF(AND(P8="Explained: Starter",C8>=1500),"High",IF(ABS(L8)>=2000,"High",IF(ABS(L8)>=500,"Medium","Low"))))) | T8: =SUMIFS('Payment Breakdown Prior'!$S$15:$S$164,'Payment Breakdown Prior'!$AE$15:$AE$164,$A8) | U8: =SUMIFS('Payment Breakdown Current'!$S$15:$S$164,'Payment Breakdown Current'!$AE$15:$AE$164,$A8) | V8: =IFERROR((U8-T8)/T8,"") | W8: =(SUMIFS('Payment Breakdown Current'!$S$15:$S$164,'Payment Breakdown Current'!$AE$15:$AE$164,$A8))-(SUMIFS('Payment Breakdown Prior'!$S$15:$S$164,'Payment Breakdown Prior'!$AE$15:$AE$164,$A8)) | X8: =(SUMIFS('Payment Breakdown Current'!$T$15:$T$164,'Payment Breakdown Current'!$AE$15:$AE$164,$A8))-(SUMIFS('Payment Breakdown Prior'!$T$15:$T$164,'Payment Breakdown Prior'!$AE$15:$AE$164,$A8)) | Y8: =(SUMIFS('Payment Breakdown Current'!$U$15:$U$164,'Payment Breakdown Current'!$AE$15:$AE$164,$A8))-(SUMIFS('Payment Breakdown Prior'!$U$15:$U$164,'Payment Breakdown Prior'!$AE$15:$AE$164,$A8)) | Z8: =(SUMIFS('Payment Breakdown Current'!$V$15:$V$164,'Payment Breakdown Current'!$AE$15:$AE$164,$A8))-(SUMIFS('Payment Breakdown Prior'!$V$15:$V$164,'Payment Breakdown Prior'!$AE$15:$AE$164,$A8)) | AA8: =(SUMIFS('Payment Breakdown Current'!$W$15:$W$164,'Payment Breakdown Current'!$AE$15:$AE$164,$A8))-(SUMIFS('Payment Breakdown Prior'!$W$15:$W$164,'Payment Breakdown Prior'!$AE$15:$AE$164,$A8)) | AB8: =(SUMIFS('Payment Breakdown Current'!$X$15:$X$164,'Payment Breakdown Current'!$AE$15:$AE$164,$A8))-(SUMIFS('Payment Breakdown Prior'!$X$15:$X$164,'Payment Breakdown Prior'!$AE$15:$AE$164,$A8)) | AC8: =(SUMIFS('Payment Breakdown Current'!$Y$15:$Y$164,'Payment Breakdown Current'!$AE$15:$AE$164,$A8))-(SUMIFS('Payment Breakdown Prior'!$Y$15:$Y$164,'Payment Breakdown Prior'!$AE$15:$AE$164,$A8)) | AD8: =(SUMIFS('Payment Breakdown Current'!$Z$15:$Z$164,'Payment Breakdown Current'!$AE$15:$AE$164,$A8))-(SUMIFS('Payment Breakdown Prior'!$Z$15:$Z$164,'Payment Breakdown Prior'!$AE$15:$AE$164,$A8)) | AE8: =(SUMIFS('Payment Breakdown Current'!$AA$15:$AA$164,'Payment Breakdown Current'!$AE$15:$AE$164,$A8))-(SUMIFS('Payment Breakdown Prior'!$AA$15:$AA$164,'Payment Breakdown Prior'!$AE$15:$AE$164,$A8)) | AF8: =(SUMIFS('Payment Breakdown Current'!$AB$15:$AB$164,'Payment Breakdown Current'!$AE$15:$AE$164,$A8))-(SUMIFS('Payment Breakdown Prior'!$AB$15:$AB$164,'Payment Breakdown Prior'!$AE$15:$AE$164,$A8)) | AG8: =(SUMIFS('Payment Breakdown Current'!$AC$15:$AC$164,'Payment Breakdown Current'!$AE$15:$AE$164,$A8))-(SUMIFS('Payment Breakdown Prior'!$AC$15:$AC$164,'Payment Breakdown Prior'!$AE$15:$AE$164,$A8)) | AH8: =(SUMIFS('Payment Breakdown Current'!$AD$15:$AD$164,'Payment Breakdown Current'!$AE$15:$AE$164,$A8))-(SUMIFS('Payment Breakdown Prior'!$AD$15:$AD$164,'Payment Breakdown Prior'!$AE$15:$AE$164,$A8)) | AI8: {=MAX(ABS(W8:AH8))} | AJ8: {=IF(AI8<0.005,"",IFERROR(INDEX($W$1:$AH$1,MATCH(AI8,ABS(W8:AH8),0)),""))} | AK8: {=IF(AI8<0.005,"",IFERROR(INDEX(W8:AH8,MATCH(AI8,ABS(W8:AH8),0)),""))} | AL8: =IF(R8=1,ABS(L8)-ROW()/100000000,"")
A9: =IF('NPV Comparison'!D22="","",'NPV Comparison'!D22) | B9: =IF('NPV Comparison'!E22="","",'NPV Comparison'!E22) | C9: =IF('NPV Comparison'!F22="","",'NPV Comparison'!F22) | D9: =IF($A9="","",IFERROR(INDEX(Structure!$E$13:$E$312,MATCH($A9,Structure!$P$13:$P$312,0)),"")) | E9: =IF($A9="",0,IF(COUNTIF(Structure!$P$13:$P$312,$A9)=0,0,IF(COUNTIFS(Structure!$P$13:$P$312,$A9,Structure!$N$13:$N$312,"<>Zero Hours")=0,1,0))) | F9: =IF($A9="",0,1-E9) | G9: =IF($A9="",0,IF(COUNTIF('New Starters'!$D$14:$D$73,$A9)>0,1,0)) | H9: =IF($A9="",0,IF(COUNTIF('Leavers'!$D$12:$D$71,$A9)>0,1,0)) | I9: =IF($A9="","",IFERROR(INDEX('New Starters'!$K$14:$K$73,MATCH($A9,'New Starters'!$D$14:$D$73,0)),IFERROR(INDEX('Leavers'!$K$12:$K$71,MATCH($A9,'Leavers'!$D$12:$D$71,0)),""))) | J9: =IF(AND(G9=1,I9<>"",COUNTIF('Leavers'!$K$12:$K$71,I9)>0),1,IF(AND(H9=1,I9<>"",COUNTIF('New Starters'!$K$14:$K$73,I9)>0),1,0)) | K9: =IF(ISNUMBER(SEARCH("Head Office",D9)),'Control Sheet'!$C$6,'Control Sheet'!$C$5) | L9: =IF(OR($A9="",AND(B9="",C9="")),"",IF(B9="",C9,IF(C9="",-B9,C9-B9))) | M9: =IFERROR(L9/B9,"") | N9: =IF($A9="",0,IF(OR(B9="",C9="",C9=0,AND(ISNUMBER(M9),ABS(M9)>K9)),1,0)) | O9: =IF(AND(N9=1,ABS(L9)>='Control Sheet'!$C$7,F9=1),1,0) | P9: =IF($A9="","",IF(F9=0,"Zero Hours",IF(J9=1,"Explained: Paired transfer",IF(AND(G9=1,H9=0,J9=0),"Explained: Starter",IF(AND(H9=1,G9=0,J9=0),"Explained: Leaver",IF(O9=1,"Review required","OK")))))) | Q9: =IF(AND(F9=1,OR(C9="",C9=0),H9=0,J9=0),1,0) | R9: =IF(F9=0,0,IF(P9="Review required",1,IF(AND(P9="Explained: Starter",ISNUMBER(C9),C9>=1500),1,0))) | S9: =IF(R9=0,"",IF(Q9=1,"High",IF(AND(P9="Explained: Starter",C9>=1500),"High",IF(ABS(L9)>=2000,"High",IF(ABS(L9)>=500,"Medium","Low"))))) | T9: =SUMIFS('Payment Breakdown Prior'!$S$15:$S$164,'Payment Breakdown Prior'!$AE$15:$AE$164,$A9) | U9: =SUMIFS('Payment Breakdown Current'!$S$15:$S$164,'Payment Breakdown Current'!$AE$15:$AE$164,$A9) | V9: =IFERROR((U9-T9)/T9,"") | W9: =(SUMIFS('Payment Breakdown Current'!$S$15:$S$164,'Payment Breakdown Current'!$AE$15:$AE$164,$A9))-(SUMIFS('Payment Breakdown Prior'!$S$15:$S$164,'Payment Breakdown Prior'!$AE$15:$AE$164,$A9)) | X9: =(SUMIFS('Payment Breakdown Current'!$T$15:$T$164,'Payment Breakdown Current'!$AE$15:$AE$164,$A9))-(SUMIFS('Payment Breakdown Prior'!$T$15:$T$164,'Payment Breakdown Prior'!$AE$15:$AE$164,$A9)) | Y9: =(SUMIFS('Payment Breakdown Current'!$U$15:$U$164,'Payment Breakdown Current'!$AE$15:$AE$164,$A9))-(SUMIFS('Payment Breakdown Prior'!$U$15:$U$164,'Payment Breakdown Prior'!$AE$15:$AE$164,$A9)) | Z9: =(SUMIFS('Payment Breakdown Current'!$V$15:$V$164,'Payment Breakdown Current'!$AE$15:$AE$164,$A9))-(SUMIFS('Payment Breakdown Prior'!$V$15:$V$164,'Payment Breakdown Prior'!$AE$15:$AE$164,$A9)) | AA9: =(SUMIFS('Payment Breakdown Current'!$W$15:$W$164,'Payment Breakdown Current'!$AE$15:$AE$164,$A9))-(SUMIFS('Payment Breakdown Prior'!$W$15:$W$164,'Payment Breakdown Prior'!$AE$15:$AE$164,$A9)) | AB9: =(SUMIFS('Payment Breakdown Current'!$X$15:$X$164,'Payment Breakdown Current'!$AE$15:$AE$164,$A9))-(SUMIFS('Payment Breakdown Prior'!$X$15:$X$164,'Payment Breakdown Prior'!$AE$15:$AE$164,$A9)) | AC9: =(SUMIFS('Payment Breakdown Current'!$Y$15:$Y$164,'Payment Breakdown Current'!$AE$15:$AE$164,$A9))-(SUMIFS('Payment Breakdown Prior'!$Y$15:$Y$164,'Payment Breakdown Prior'!$AE$15:$AE$164,$A9)) | AD9: =(SUMIFS('Payment Breakdown Current'!$Z$15:$Z$164,'Payment Breakdown Current'!$AE$15:$AE$164,$A9))-(SUMIFS('Payment Breakdown Prior'!$Z$15:$Z$164,'Payment Breakdown Prior'!$AE$15:$AE$164,$A9)) | AE9: =(SUMIFS('Payment Breakdown Current'!$AA$15:$AA$164,'Payment Breakdown Current'!$AE$15:$AE$164,$A9))-(SUMIFS('Payment Breakdown Prior'!$AA$15:$AA$164,'Payment Breakdown Prior'!$AE$15:$AE$164,$A9)) | AF9: =(SUMIFS('Payment Breakdown Current'!$AB$15:$AB$164,'Payment Breakdown Current'!$AE$15:$AE$164,$A9))-(SUMIFS('Payment Breakdown Prior'!$AB$15:$AB$164,'Payment Breakdown Prior'!$AE$15:$AE$164,$A9)) | AG9: =(SUMIFS('Payment Breakdown Current'!$AC$15:$AC$164,'Payment Breakdown Current'!$AE$15:$AE$164,$A9))-(SUMIFS('Payment Breakdown Prior'!$AC$15:$AC$164,'Payment Breakdown Prior'!$AE$15:$AE$164,$A9)) | AH9: =(SUMIFS('Payment Breakdown Current'!$AD$15:$AD$164,'Payment Breakdown Current'!$AE$15:$AE$164,$A9))-(SUMIFS('Payment Breakdown Prior'!$AD$15:$AD$164,'Payment Breakdown Prior'!$AE$15:$AE$164,$A9)) | AI9: {=MAX(ABS(W9:AH9))} | AJ9: {=IF(AI9<0.005,"",IFERROR(INDEX($W$1:$AH$1,MATCH(AI9,ABS(W9:AH9),0)),""))} | AK9: {=IF(AI9<0.005,"",IFERROR(INDEX(W9:AH9,MATCH(AI9,ABS(W9:AH9),0)),""))} | AL9: =IF(R9=1,ABS(L9)-ROW()/100000000,"")
A10: =IF('NPV Comparison'!D23="","",'NPV Comparison'!D23) | B10: =IF('NPV Comparison'!E23="","",'NPV Comparison'!E23) | C10: =IF('NPV Comparison'!F23="","",'NPV Comparison'!F23) | D10: =IF($A10="","",IFERROR(INDEX(Structure!$E$13:$E$312,MATCH($A10,Structure!$P$13:$P$312,0)),"")) | E10: =IF($A10="",0,IF(COUNTIF(Structure!$P$13:$P$312,$A10)=0,0,IF(COUNTIFS(Structure!$P$13:$P$312,$A10,Structure!$N$13:$N$312,"<>Zero Hours")=0,1,0))) | F10: =IF($A10="",0,1-E10) | G10: =IF($A10="",0,IF(COUNTIF('New Starters'!$D$14:$D$73,$A10)>0,1,0)) | H10: =IF($A10="",0,IF(COUNTIF('Leavers'!$D$12:$D$71,$A10)>0,1,0)) | I10: =IF($A10="","",IFERROR(INDEX('New Starters'!$K$14:$K$73,MATCH($A10,'New Starters'!$D$14:$D$73,0)),IFERROR(INDEX('Leavers'!$K$12:$K$71,MATCH($A10,'Leavers'!$D$12:$D$71,0)),""))) | J10: =IF(AND(G10=1,I10<>"",COUNTIF('Leavers'!$K$12:$K$71,I10)>0),1,IF(AND(H10=1,I10<>"",COUNTIF('New Starters'!$K$14:$K$73,I10)>0),1,0)) | K10: =IF(ISNUMBER(SEARCH("Head Office",D10)),'Control Sheet'!$C$6,'Control Sheet'!$C$5) | L10: =IF(OR($A10="",AND(B10="",C10="")),"",IF(B10="",C10,IF(C10="",-B10,C10-B10))) | M10: =IFERROR(L10/B10,"") | N10: =IF($A10="",0,IF(OR(B10="",C10="",C10=0,AND(ISNUMBER(M10),ABS(M10)>K10)),1,0)) | O10: =IF(AND(N10=1,ABS(L10)>='Control Sheet'!$C$7,F10=1),1,0) | P10: =IF($A10="","",IF(F10=0,"Zero Hours",IF(J10=1,"Explained: Paired transfer",IF(AND(G10=1,H10=0,J10=0),"Explained: Starter",IF(AND(H10=1,G10=0,J10=0),"Explained: Leaver",IF(O10=1,"Review required","OK")))))) | Q10: =IF(AND(F10=1,OR(C10="",C10=0),H10=0,J10=0),1,0) | R10: =IF(F10=0,0,IF(P10="Review required",1,IF(AND(P10="Explained: Starter",ISNUMBER(C10),C10>=1500),1,0))) | S10: =IF(R10=0,"",IF(Q10=1,"High",IF(AND(P10="Explained: Starter",C10>=1500),"High",IF(ABS(L10)>=2000,"High",IF(ABS(L10)>=500,"Medium","Low"))))) | T10: =SUMIFS('Payment Breakdown Prior'!$S$15:$S$164,'Payment Breakdown Prior'!$AE$15:$AE$164,$A10) | U10: =SUMIFS('Payment Breakdown Current'!$S$15:$S$164,'Payment Breakdown Current'!$AE$15:$AE$164,$A10) | V10: =IFERROR((U10-T10)/T10,"") | W10: =(SUMIFS('Payment Breakdown Current'!$S$15:$S$164,'Payment Breakdown Current'!$AE$15:$AE$164,$A10))-(SUMIFS('Payment Breakdown Prior'!$S$15:$S$164,'Payment Breakdown Prior'!$AE$15:$AE$164,$A10)) | X10: =(SUMIFS('Payment Breakdown Current'!$T$15:$T$164,'Payment Breakdown Current'!$AE$15:$AE$164,$A10))-(SUMIFS('Payment Breakdown Prior'!$T$15:$T$164,'Payment Breakdown Prior'!$AE$15:$AE$164,$A10)) | Y10: =(SUMIFS('Payment Breakdown Current'!$U$15:$U$164,'Payment Breakdown Current'!$AE$15:$AE$164,$A10))-(SUMIFS('Payment Breakdown Prior'!$U$15:$U$164,'Payment Breakdown Prior'!$AE$15:$AE$164,$A10)) | Z10: =(SUMIFS('Payment Breakdown Current'!$V$15:$V$164,'Payment Breakdown Current'!$AE$15:$AE$164,$A10))-(SUMIFS('Payment Breakdown Prior'!$V$15:$V$164,'Payment Breakdown Prior'!$AE$15:$AE$164,$A10)) | AA10: =(SUMIFS('Payment Breakdown Current'!$W$15:$W$164,'Payment Breakdown Current'!$AE$15:$AE$164,$A10))-(SUMIFS('Payment Breakdown Prior'!$W$15:$W$164,'Payment Breakdown Prior'!$AE$15:$AE$164,$A10)) | AB10: =(SUMIFS('Payment Breakdown Current'!$X$15:$X$164,'Payment Breakdown Current'!$AE$15:$AE$164,$A10))-(SUMIFS('Payment Breakdown Prior'!$X$15:$X$164,'Payment Breakdown Prior'!$AE$15:$AE$164,$A10)) | AC10: =(SUMIFS('Payment Breakdown Current'!$Y$15:$Y$164,'Payment Breakdown Current'!$AE$15:$AE$164,$A10))-(SUMIFS('Payment Breakdown Prior'!$Y$15:$Y$164,'Payment Breakdown Prior'!$AE$15:$AE$164,$A10)) | AD10: =(SUMIFS('Payment Breakdown Current'!$Z$15:$Z$164,'Payment Breakdown Current'!$AE$15:$AE$164,$A10))-(SUMIFS('Payment Breakdown Prior'!$Z$15:$Z$164,'Payment Breakdown Prior'!$AE$15:$AE$164,$A10)) | AE10: =(SUMIFS('Payment Breakdown Current'!$AA$15:$AA$164,'Payment Breakdown Current'!$AE$15:$AE$164,$A10))-(SUMIFS('Payment Breakdown Prior'!$AA$15:$AA$164,'Payment Breakdown Prior'!$AE$15:$AE$164,$A10)) | AF10: =(SUMIFS('Payment Breakdown Current'!$AB$15:$AB$164,'Payment Breakdown Current'!$AE$15:$AE$164,$A10))-(SUMIFS('Payment Breakdown Prior'!$AB$15:$AB$164,'Payment Breakdown Prior'!$AE$15:$AE$164,$A10)) | AG10: =(SUMIFS('Payment Breakdown Current'!$AC$15:$AC$164,'Payment Breakdown Current'!$AE$15:$AE$164,$A10))-(SUMIFS('Payment Breakdown Prior'!$AC$15:$AC$164,'Payment Breakdown Prior'!$AE$15:$AE$164,$A10)) | AH10: =(SUMIFS('Payment Breakdown Current'!$AD$15:$AD$164,'Payment Breakdown Current'!$AE$15:$AE$164,$A10))-(SUMIFS('Payment Breakdown Prior'!$AD$15:$AD$164,'Payment Breakdown Prior'!$AE$15:$AE$164,$A10)) | AI10: {=MAX(ABS(W10:AH10))} | AJ10: {=IF(AI10<0.005,"",IFERROR(INDEX($W$1:$AH$1,MATCH(AI10,ABS(W10:AH10),0)),""))} | AK10: {=IF(AI10<0.005,"",IFERROR(INDEX(W10:AH10,MATCH(AI10,ABS(W10:AH10),0)),""))} | AL10: =IF(R10=1,ABS(L10)-ROW()/100000000,"")
A11: =IF('NPV Comparison'!D24="","",'NPV Comparison'!D24) | B11: =IF('NPV Comparison'!E24="","",'NPV Comparison'!E24) | C11: =IF('NPV Comparison'!F24="","",'NPV Comparison'!F24) | D11: =IF($A11="","",IFERROR(INDEX(Structure!$E$13:$E$312,MATCH($A11,Structure!$P$13:$P$312,0)),"")) | E11: =IF($A11="",0,IF(COUNTIF(Structure!$P$13:$P$312,$A11)=0,0,IF(COUNTIFS(Structure!$P$13:$P$312,$A11,Structure!$N$13:$N$312,"<>Zero Hours")=0,1,0))) | F11: =IF($A11="",0,1-E11) | G11: =IF($A11="",0,IF(COUNTIF('New Starters'!$D$14:$D$73,$A11)>0,1,0)) | H11: =IF($A11="",0,IF(COUNTIF('Leavers'!$D$12:$D$71,$A11)>0,1,0)) | I11: =IF($A11="","",IFERROR(INDEX('New Starters'!$K$14:$K$73,MATCH($A11,'New Starters'!$D$14:$D$73,0)),IFERROR(INDEX('Leavers'!$K$12:$K$71,MATCH($A11,'Leavers'!$D$12:$D$71,0)),""))) | J11: =IF(AND(G11=1,I11<>"",COUNTIF('Leavers'!$K$12:$K$71,I11)>0),1,IF(AND(H11=1,I11<>"",COUNTIF('New Starters'!$K$14:$K$73,I11)>0),1,0)) | K11: =IF(ISNUMBER(SEARCH("Head Office",D11)),'Control Sheet'!$C$6,'Control Sheet'!$C$5) | L11: =IF(OR($A11="",AND(B11="",C11="")),"",IF(B11="",C11,IF(C11="",-B11,C11-B11))) | M11: =IFERROR(L11/B11,"") | N11: =IF($A11="",0,IF(OR(B11="",C11="",C11=0,AND(ISNUMBER(M11),ABS(M11)>K11)),1,0)) | O11: =IF(AND(N11=1,ABS(L11)>='Control Sheet'!$C$7,F11=1),1,0) | P11: =IF($A11="","",IF(F11=0,"Zero Hours",IF(J11=1,"Explained: Paired transfer",IF(AND(G11=1,H11=0,J11=0),"Explained: Starter",IF(AND(H11=1,G11=0,J11=0),"Explained: Leaver",IF(O11=1,"Review required","OK")))))) | Q11: =IF(AND(F11=1,OR(C11="",C11=0),H11=0,J11=0),1,0) | R11: =IF(F11=0,0,IF(P11="Review required",1,IF(AND(P11="Explained: Starter",ISNUMBER(C11),C11>=1500),1,0))) | S11: =IF(R11=0,"",IF(Q11=1,"High",IF(AND(P11="Explained: Starter",C11>=1500),"High",IF(ABS(L11)>=2000,"High",IF(ABS(L11)>=500,"Medium","Low"))))) | T11: =SUMIFS('Payment Breakdown Prior'!$S$15:$S$164,'Payment Breakdown Prior'!$AE$15:$AE$164,$A11) | U11: =SUMIFS('Payment Breakdown Current'!$S$15:$S$164,'Payment Breakdown Current'!$AE$15:$AE$164,$A11) | V11: =IFERROR((U11-T11)/T11,"") | W11: =(SUMIFS('Payment Breakdown Current'!$S$15:$S$164,'Payment Breakdown Current'!$AE$15:$AE$164,$A11))-(SUMIFS('Payment Breakdown Prior'!$S$15:$S$164,'Payment Breakdown Prior'!$AE$15:$AE$164,$A11)) | X11: =(SUMIFS('Payment Breakdown Current'!$T$15:$T$164,'Payment Breakdown Current'!$AE$15:$AE$164,$A11))-(SUMIFS('Payment Breakdown Prior'!$T$15:$T$164,'Payment Breakdown Prior'!$AE$15:$AE$164,$A11)) | Y11: =(SUMIFS('Payment Breakdown Current'!$U$15:$U$164,'Payment Breakdown Current'!$AE$15:$AE$164,$A11))-(SUMIFS('Payment Breakdown Prior'!$U$15:$U$164,'Payment Breakdown Prior'!$AE$15:$AE$164,$A11)) | Z11: =(SUMIFS('Payment Breakdown Current'!$V$15:$V$164,'Payment Breakdown Current'!$AE$15:$AE$164,$A11))-(SUMIFS('Payment Breakdown Prior'!$V$15:$V$164,'Payment Breakdown Prior'!$AE$15:$AE$164,$A11)) | AA11: =(SUMIFS('Payment Breakdown Current'!$W$15:$W$164,'Payment Breakdown Current'!$AE$15:$AE$164,$A11))-(SUMIFS('Payment Breakdown Prior'!$W$15:$W$164,'Payment Breakdown Prior'!$AE$15:$AE$164,$A11)) | AB11: =(SUMIFS('Payment Breakdown Current'!$X$15:$X$164,'Payment Breakdown Current'!$AE$15:$AE$164,$A11))-(SUMIFS('Payment Breakdown Prior'!$X$15:$X$164,'Payment Breakdown Prior'!$AE$15:$AE$164,$A11)) | AC11: =(SUMIFS('Payment Breakdown Current'!$Y$15:$Y$164,'Payment Breakdown Current'!$AE$15:$AE$164,$A11))-(SUMIFS('Payment Breakdown Prior'!$Y$15:$Y$164,'Payment Breakdown Prior'!$AE$15:$AE$164,$A11)) | AD11: =(SUMIFS('Payment Breakdown Current'!$Z$15:$Z$164,'Payment Breakdown Current'!$AE$15:$AE$164,$A11))-(SUMIFS('Payment Breakdown Prior'!$Z$15:$Z$164,'Payment Breakdown Prior'!$AE$15:$AE$164,$A11)) | AE11: =(SUMIFS('Payment Breakdown Current'!$AA$15:$AA$164,'Payment Breakdown Current'!$AE$15:$AE$164,$A11))-(SUMIFS('Payment Breakdown Prior'!$AA$15:$AA$164,'Payment Breakdown Prior'!$AE$15:$AE$164,$A11)) | AF11: =(SUMIFS('Payment Breakdown Current'!$AB$15:$AB$164,'Payment Breakdown Current'!$AE$15:$AE$164,$A11))-(SUMIFS('Payment Breakdown Prior'!$AB$15:$AB$164,'Payment Breakdown Prior'!$AE$15:$AE$164,$A11)) | AG11: =(SUMIFS('Payment Breakdown Current'!$AC$15:$AC$164,'Payment Breakdown Current'!$AE$15:$AE$164,$A11))-(SUMIFS('Payment Breakdown Prior'!$AC$15:$AC$164,'Payment Breakdown Prior'!$AE$15:$AE$164,$A11)) | AH11: =(SUMIFS('Payment Breakdown Current'!$AD$15:$AD$164,'Payment Breakdown Current'!$AE$15:$AE$164,$A11))-(SUMIFS('Payment Breakdown Prior'!$AD$15:$AD$164,'Payment Breakdown Prior'!$AE$15:$AE$164,$A11)) | AI11: {=MAX(ABS(W11:AH11))} | AJ11: {=IF(AI11<0.005,"",IFERROR(INDEX($W$1:$AH$1,MATCH(AI11,ABS(W11:AH11),0)),""))} | AK11: {=IF(AI11<0.005,"",IFERROR(INDEX(W11:AH11,MATCH(AI11,ABS(W11:AH11),0)),""))} | AL11: =IF(R11=1,ABS(L11)-ROW()/100000000,"")
A12: =IF('NPV Comparison'!D25="","",'NPV Comparison'!D25) | B12: =IF('NPV Comparison'!E25="","",'NPV Comparison'!E25) | C12: =IF('NPV Comparison'!F25="","",'NPV Comparison'!F25) | D12: =IF($A12="","",IFERROR(INDEX(Structure!$E$13:$E$312,MATCH($A12,Structure!$P$13:$P$312,0)),"")) | E12: =IF($A12="",0,IF(COUNTIF(Structure!$P$13:$P$312,$A12)=0,0,IF(COUNTIFS(Structure!$P$13:$P$312,$A12,Structure!$N$13:$N$312,"<>Zero Hours")=0,1,0))) | F12: =IF($A12="",0,1-E12) | G12: =IF($A12="",0,IF(COUNTIF('New Starters'!$D$14:$D$73,$A12)>0,1,0)) | H12: =IF($A12="",0,IF(COUNTIF('Leavers'!$D$12:$D$71,$A12)>0,1,0)) | I12: =IF($A12="","",IFERROR(INDEX('New Starters'!$K$14:$K$73,MATCH($A12,'New Starters'!$D$14:$D$73,0)),IFERROR(INDEX('Leavers'!$K$12:$K$71,MATCH($A12,'Leavers'!$D$12:$D$71,0)),""))) | J12: =IF(AND(G12=1,I12<>"",COUNTIF('Leavers'!$K$12:$K$71,I12)>0),1,IF(AND(H12=1,I12<>"",COUNTIF('New Starters'!$K$14:$K$73,I12)>0),1,0)) | K12: =IF(ISNUMBER(SEARCH("Head Office",D12)),'Control Sheet'!$C$6,'Control Sheet'!$C$5) | L12: =IF(OR($A12="",AND(B12="",C12="")),"",IF(B12="",C12,IF(C12="",-B12,C12-B12))) | M12: =IFERROR(L12/B12,"") | N12: =IF($A12="",0,IF(OR(B12="",C12="",C12=0,AND(ISNUMBER(M12),ABS(M12)>K12)),1,0)) | O12: =IF(AND(N12=1,ABS(L12)>='Control Sheet'!$C$7,F12=1),1,0) | P12: =IF($A12="","",IF(F12=0,"Zero Hours",IF(J12=1,"Explained: Paired transfer",IF(AND(G12=1,H12=0,J12=0),"Explained: Starter",IF(AND(H12=1,G12=0,J12=0),"Explained: Leaver",IF(O12=1,"Review required","OK")))))) | Q12: =IF(AND(F12=1,OR(C12="",C12=0),H12=0,J12=0),1,0) | R12: =IF(F12=0,0,IF(P12="Review required",1,IF(AND(P12="Explained: Starter",ISNUMBER(C12),C12>=1500),1,0))) | S12: =IF(R12=0,"",IF(Q12=1,"High",IF(AND(P12="Explained: Starter",C12>=1500),"High",IF(ABS(L12)>=2000,"High",IF(ABS(L12)>=500,"Medium","Low"))))) | T12: =SUMIFS('Payment Breakdown Prior'!$S$15:$S$164,'Payment Breakdown Prior'!$AE$15:$AE$164,$A12) | U12: =SUMIFS('Payment Breakdown Current'!$S$15:$S$164,'Payment Breakdown Current'!$AE$15:$AE$164,$A12) | V12: =IFERROR((U12-T12)/T12,"") | W12: =(SUMIFS('Payment Breakdown Current'!$S$15:$S$164,'Payment Breakdown Current'!$AE$15:$AE$164,$A12))-(SUMIFS('Payment Breakdown Prior'!$S$15:$S$164,'Payment Breakdown Prior'!$AE$15:$AE$164,$A12)) | X12: =(SUMIFS('Payment Breakdown Current'!$T$15:$T$164,'Payment Breakdown Current'!$AE$15:$AE$164,$A12))-(SUMIFS('Payment Breakdown Prior'!$T$15:$T$164,'Payment Breakdown Prior'!$AE$15:$AE$164,$A12)) | Y12: =(SUMIFS('Payment Breakdown Current'!$U$15:$U$164,'Payment Breakdown Current'!$AE$15:$AE$164,$A12))-(SUMIFS('Payment Breakdown Prior'!$U$15:$U$164,'Payment Breakdown Prior'!$AE$15:$AE$164,$A12)) | Z12: =(SUMIFS('Payment Breakdown Current'!$V$15:$V$164,'Payment Breakdown Current'!$AE$15:$AE$164,$A12))-(SUMIFS('Payment Breakdown Prior'!$V$15:$V$164,'Payment Breakdown Prior'!$AE$15:$AE$164,$A12)) | AA12: =(SUMIFS('Payment Breakdown Current'!$W$15:$W$164,'Payment Breakdown Current'!$AE$15:$AE$164,$A12))-(SUMIFS('Payment Breakdown Prior'!$W$15:$W$164,'Payment Breakdown Prior'!$AE$15:$AE$164,$A12)) | AB12: =(SUMIFS('Payment Breakdown Current'!$X$15:$X$164,'Payment Breakdown Current'!$AE$15:$AE$164,$A12))-(SUMIFS('Payment Breakdown Prior'!$X$15:$X$164,'Payment Breakdown Prior'!$AE$15:$AE$164,$A12)) | AC12: =(SUMIFS('Payment Breakdown Current'!$Y$15:$Y$164,'Payment Breakdown Current'!$AE$15:$AE$164,$A12))-(SUMIFS('Payment Breakdown Prior'!$Y$15:$Y$164,'Payment Breakdown Prior'!$AE$15:$AE$164,$A12)) | AD12: =(SUMIFS('Payment Breakdown Current'!$Z$15:$Z$164,'Payment Breakdown Current'!$AE$15:$AE$164,$A12))-(SUMIFS('Payment Breakdown Prior'!$Z$15:$Z$164,'Payment Breakdown Prior'!$AE$15:$AE$164,$A12)) | AE12: =(SUMIFS('Payment Breakdown Current'!$AA$15:$AA$164,'Payment Breakdown Current'!$AE$15:$AE$164,$A12))-(SUMIFS('Payment Breakdown Prior'!$AA$15:$AA$164,'Payment Breakdown Prior'!$AE$15:$AE$164,$A12)) | AF12: =(SUMIFS('Payment Breakdown Current'!$AB$15:$AB$164,'Payment Breakdown Current'!$AE$15:$AE$164,$A12))-(SUMIFS('Payment Breakdown Prior'!$AB$15:$AB$164,'Payment Breakdown Prior'!$AE$15:$AE$164,$A12)) | AG12: =(SUMIFS('Payment Breakdown Current'!$AC$15:$AC$164,'Payment Breakdown Current'!$AE$15:$AE$164,$A12))-(SUMIFS('Payment Breakdown Prior'!$AC$15:$AC$164,'Payment Breakdown Prior'!$AE$15:$AE$164,$A12)) | AH12: =(SUMIFS('Payment Breakdown Current'!$AD$15:$AD$164,'Payment Breakdown Current'!$AE$15:$AE$164,$A12))-(SUMIFS('Payment Breakdown Prior'!$AD$15:$AD$164,'Payment Breakdown Prior'!$AE$15:$AE$164,$A12)) | AI12: {=MAX(ABS(W12:AH12))} | AJ12: {=IF(AI12<0.005,"",IFERROR(INDEX($W$1:$AH$1,MATCH(AI12,ABS(W12:AH12),0)),""))} | AK12: {=IF(AI12<0.005,"",IFERROR(INDEX(W12:AH12,MATCH(AI12,ABS(W12:AH12),0)),""))} | AL12: =IF(R12=1,ABS(L12)-ROW()/100000000,"")
A13: =IF('NPV Comparison'!D26="","",'NPV Comparison'!D26) | B13: =IF('NPV Comparison'!E26="","",'NPV Comparison'!E26) | C13: =IF('NPV Comparison'!F26="","",'NPV Comparison'!F26) | D13: =IF($A13="","",IFERROR(INDEX(Structure!$E$13:$E$312,MATCH($A13,Structure!$P$13:$P$312,0)),"")) | E13: =IF($A13="",0,IF(COUNTIF(Structure!$P$13:$P$312,$A13)=0,0,IF(COUNTIFS(Structure!$P$13:$P$312,$A13,Structure!$N$13:$N$312,"<>Zero Hours")=0,1,0))) | F13: =IF($A13="",0,1-E13) | G13: =IF($A13="",0,IF(COUNTIF('New Starters'!$D$14:$D$73,$A13)>0,1,0)) | H13: =IF($A13="",0,IF(COUNTIF('Leavers'!$D$12:$D$71,$A13)>0,1,0)) | I13: =IF($A13="","",IFERROR(INDEX('New Starters'!$K$14:$K$73,MATCH($A13,'New Starters'!$D$14:$D$73,0)),IFERROR(INDEX('Leavers'!$K$12:$K$71,MATCH($A13,'Leavers'!$D$12:$D$71,0)),""))) | J13: =IF(AND(G13=1,I13<>"",COUNTIF('Leavers'!$K$12:$K$71,I13)>0),1,IF(AND(H13=1,I13<>"",COUNTIF('New Starters'!$K$14:$K$73,I13)>0),1,0)) | K13: =IF(ISNUMBER(SEARCH("Head Office",D13)),'Control Sheet'!$C$6,'Control Sheet'!$C$5) | L13: =IF(OR($A13="",AND(B13="",C13="")),"",IF(B13="",C13,IF(C13="",-B13,C13-B13))) | M13: =IFERROR(L13/B13,"") | N13: =IF($A13="",0,IF(OR(B13="",C13="",C13=0,AND(ISNUMBER(M13),ABS(M13)>K13)),1,0)) | O13: =IF(AND(N13=1,ABS(L13)>='Control Sheet'!$C$7,F13=1),1,0) | P13: =IF($A13="","",IF(F13=0,"Zero Hours",IF(J13=1,"Explained: Paired transfer",IF(AND(G13=1,H13=0,J13=0),"Explained: Starter",IF(AND(H13=1,G13=0,J13=0),"Explained: Leaver",IF(O13=1,"Review required","OK")))))) | Q13: =IF(AND(F13=1,OR(C13="",C13=0),H13=0,J13=0),1,0) | R13: =IF(F13=0,0,IF(P13="Review required",1,IF(AND(P13="Explained: Starter",ISNUMBER(C13),C13>=1500),1,0))) | S13: =IF(R13=0,"",IF(Q13=1,"High",IF(AND(P13="Explained: Starter",C13>=1500),"High",IF(ABS(L13)>=2000,"High",IF(ABS(L13)>=500,"Medium","Low"))))) | T13: =SUMIFS('Payment Breakdown Prior'!$S$15:$S$164,'Payment Breakdown Prior'!$AE$15:$AE$164,$A13) | U13: =SUMIFS('Payment Breakdown Current'!$S$15:$S$164,'Payment Breakdown Current'!$AE$15:$AE$164,$A13) | V13: =IFERROR((U13-T13)/T13,"") | W13: =(SUMIFS('Payment Breakdown Current'!$S$15:$S$164,'Payment Breakdown Current'!$AE$15:$AE$164,$A13))-(SUMIFS('Payment Breakdown Prior'!$S$15:$S$164,'Payment Breakdown Prior'!$AE$15:$AE$164,$A13)) | X13: =(SUMIFS('Payment Breakdown Current'!$T$15:$T$164,'Payment Breakdown Current'!$AE$15:$AE$164,$A13))-(SUMIFS('Payment Breakdown Prior'!$T$15:$T$164,'Payment Breakdown Prior'!$AE$15:$AE$164,$A13)) | Y13: =(SUMIFS('Payment Breakdown Current'!$U$15:$U$164,'Payment Breakdown Current'!$AE$15:$AE$164,$A13))-(SUMIFS('Payment Breakdown Prior'!$U$15:$U$164,'Payment Breakdown Prior'!$AE$15:$AE$164,$A13)) | Z13: =(SUMIFS('Payment Breakdown Current'!$V$15:$V$164,'Payment Breakdown Current'!$AE$15:$AE$164,$A13))-(SUMIFS('Payment Breakdown Prior'!$V$15:$V$164,'Payment Breakdown Prior'!$AE$15:$AE$164,$A13)) | AA13: =(SUMIFS('Payment Breakdown Current'!$W$15:$W$164,'Payment Breakdown Current'!$AE$15:$AE$164,$A13))-(SUMIFS('Payment Breakdown Prior'!$W$15:$W$164,'Payment Breakdown Prior'!$AE$15:$AE$164,$A13)) | AB13: =(SUMIFS('Payment Breakdown Current'!$X$15:$X$164,'Payment Breakdown Current'!$AE$15:$AE$164,$A13))-(SUMIFS('Payment Breakdown Prior'!$X$15:$X$164,'Payment Breakdown Prior'!$AE$15:$AE$164,$A13)) | AC13: =(SUMIFS('Payment Breakdown Current'!$Y$15:$Y$164,'Payment Breakdown Current'!$AE$15:$AE$164,$A13))-(SUMIFS('Payment Breakdown Prior'!$Y$15:$Y$164,'Payment Breakdown Prior'!$AE$15:$AE$164,$A13)) | AD13: =(SUMIFS('Payment Breakdown Current'!$Z$15:$Z$164,'Payment Breakdown Current'!$AE$15:$AE$164,$A13))-(SUMIFS('Payment Breakdown Prior'!$Z$15:$Z$164,'Payment Breakdown Prior'!$AE$15:$AE$164,$A13)) | AE13: =(SUMIFS('Payment Breakdown Current'!$AA$15:$AA$164,'Payment Breakdown Current'!$AE$15:$AE$164,$A13))-(SUMIFS('Payment Breakdown Prior'!$AA$15:$AA$164,'Payment Breakdown Prior'!$AE$15:$AE$164,$A13)) | AF13: =(SUMIFS('Payment Breakdown Current'!$AB$15:$AB$164,'Payment Breakdown Current'!$AE$15:$AE$164,$A13))-(SUMIFS('Payment Breakdown Prior'!$AB$15:$AB$164,'Payment Breakdown Prior'!$AE$15:$AE$164,$A13)) | AG13: =(SUMIFS('Payment Breakdown Current'!$AC$15:$AC$164,'Payment Breakdown Current'!$AE$15:$AE$164,$A13))-(SUMIFS('Payment Breakdown Prior'!$AC$15:$AC$164,'Payment Breakdown Prior'!$AE$15:$AE$164,$A13)) | AH13: =(SUMIFS('Payment Breakdown Current'!$AD$15:$AD$164,'Payment Breakdown Current'!$AE$15:$AE$164,$A13))-(SUMIFS('Payment Breakdown Prior'!$AD$15:$AD$164,'Payment Breakdown Prior'!$AE$15:$AE$164,$A13)) | AI13: {=MAX(ABS(W13:AH13))} | AJ13: {=IF(AI13<0.005,"",IFERROR(INDEX($W$1:$AH$1,MATCH(AI13,ABS(W13:AH13),0)),""))} | AK13: {=IF(AI13<0.005,"",IFERROR(INDEX(W13:AH13,MATCH(AI13,ABS(W13:AH13),0)),""))} | AL13: =IF(R13=1,ABS(L13)-ROW()/100000000,"")
